<?xml version="1.0"?>
<robot xmlns:xacro="http://www.ros.org/wiki/xacro">

    <xacro:include filename="../inertial_macros.xacro"/>

    <material name="white">
        <color rgba="1 1 1 1"/>
    </material>

    <material name="orange">
        <color rgba="1 0.5088 0.0468 1"/>
    </material>    

    <material name="blue">
        <color rgba="0.2 0.2 1 1"/>
    </material>

    <material name="black">
        <color rgba="0 0 0 1"/>
    </material>

    <material name="darkGrey">
        <color rgba="0.175 0.175 0.175 1"/>
    </material>

    <material name="grey">
        <color rgba="0.3 0.3 0.3 1.0"/>
    </material>

    <material name="red">
        <color rgba="1 0 0 1"/>
    </material>

    <xacro:arg name="robot_name" default="robot_core"/>
    <xacro:property name="robot_name" value="$(arg robot_name)"/>

    

    <!-- BASE LINK -->

    
    <link name="${robot_name}/base_link"></link>

    <!-- BASE FOOTPRINT LINK -->
    <!-- for 2d space reference. for mapping-->
    <joint name="${robot_name}/base_footprint_joint" type="fixed">
        <parent link="${robot_name}/base_link"/>
        <child link="${robot_name}/base_footprint"/>
        <origin xyz="0 0 0" rpy="0 0 0"/>
    </joint>

    <link name="${robot_name}/base_footprint"></link>

    <!-- CHASSIS LINK-->
    <joint name="${robot_name}/chassis_joint" type="fixed">
        <parent link="${robot_name}/base_link"/>
        <child link="${robot_name}/chassis"/>
        <origin xyz="-0.15 0 -0.05"/>
    </joint>
    
    <link name="${robot_name}/chassis">
        <visual>
            <origin xyz="0.3 0 0.1"/>
            <geometry>
                <box size="0.6 0.4 0.2"/>
            </geometry>
            <material name="orange"/>
        </visual>

        <collision>
            <origin xyz="0.3 0 0.1"/>
            <geometry>
                <box size="0.6 0.4 0.2"/>
            </geometry>
        </collision>
        <xacro:inertial_box mass="3" x="0.6" y="0.4" z="0.2">
            <origin xyz="0.3 0 0.1" rpy="0 0 0"/>
        </xacro:inertial_box>
    </link>

    <gazebo reference="${robot_name}/chassis">
        <material>Gazebo/Orange</material>
    </gazebo>

    <!--LEFT WHEEL LINK-->
    <joint name="${robot_name}/left_wheel_joint" type="continuous">
        <parent link="${robot_name}/base_link"/>
        <child link="${robot_name}/left_wheel"/>
        <!-- y=+(ancho/2+grosor_rueda/2)  -->
        <origin xyz="0 0.225 0" rpy="-${pi/2} 0 0"/>
        <axis xyz="0 0 1"/>
    </joint>

    <link name="${robot_name}/left_wheel">
        <visual>
            <geometry>
                <cylinder radius="0.1" length="0.05"/>
            </geometry>
            <material name="black"/>
        </visual>

        <collision>
            <geometry>
                <cylinder radius="0.1" length="0.05"/>
            </geometry>
        </collision>
        <xacro:inertial_cylinder mass="0.2" length="0.05" radius="0.1">
            <origin xyz="0 0 0" rpy="0 0 0"/>
        </xacro:inertial_cylinder>
    </link>

    <gazebo reference="${robot_name}/left_wheel">
        <material>Gazebo/Black</material>
    </gazebo>


    <!--RIGHT WHEEL LINK-->
    <joint name="${robot_name}/right_wheel_joint" type="continuous">
        <parent link="${robot_name}/base_link"/>
        <child link="${robot_name}/right_wheel"/>
        <!-- y=-(ancho/2+grosor_rueda/2)  -->
        <origin xyz="0 -0.225 0" rpy="${pi/2} 0 0"/>
        <axis xyz="0 0 -1"/>
    </joint>

    <link name="${robot_name}/right_wheel">
        <visual>
            <geometry>
                <cylinder radius="0.1" length="0.05"/>
            </geometry>
            <material name="black"/>
        </visual>

        <collision>
            <geometry>
                <cylinder radius="0.1" length="0.05"/>
            </geometry>
        </collision>
        <xacro:inertial_cylinder mass="0.2" length="0.05" radius="0.1">
            <origin xyz="0 0 0" rpy="0 0 0"/>
        </xacro:inertial_cylinder>
    </link>

    <gazebo reference="${robot_name}/right_wheel">
        <material>Gazebo/Black</material>
    </gazebo>

    <!-- CASTER BASE LINK-->

    <joint name="${robot_name}/caster_base_joint" type="fixed">
        <parent link="${robot_name}/chassis"/>
        <child link="${robot_name}/caster_base"/>
        <origin xyz="0.5 0 0"/>
    </joint>

    <link name="${robot_name}/caster_base">
        <visual>
            <origin xyz="0 0 -0.015"/>
            <geometry>
                
                <box size="0.04 0.04 0.03"/>
            </geometry>
            <material name="black"/>
        </visual>
        
        <collision>
            <origin xyz="0 0 -0.015"/>
            <geometry>
                
                <box size="0.04 0.04 0.03"/>
            </geometry>
        </collision>


        <xacro:inertial_box mass="0.02" x="0.02" y="0.02" z="0.03">
            <origin xyz="0 0 -0.015"/>
        </xacro:inertial_box>

    </link>

    <gazebo reference="${robot_name}/caster_base">
        <material>Gazebo/Black</material>
    </gazebo>

    <!-- CASTER WHEEL LINK-->
    
    <joint name="${robot_name}/caster_wheel_joint" type="fixed">
        <parent link="${robot_name}/caster_base"/>
        <child link="${robot_name}/caster_wheel"/>
        <origin xyz="0 0 -0.03"/>
    </joint>

    <link name="${robot_name}/caster_wheel">
        <visual>
            <geometry>
                <sphere radius="0.02"/>
            </geometry>
            <material name="grey"/>
        </visual>
        
        <collision>
            <geometry>
                <sphere radius="0.02"/>
            </geometry>
        </collision>

        <xacro:inertial_sphere mass="0.01" radius="0.02">
            <origin xyz="0 0 0" rpy="0 0 0"/>
        </xacro:inertial_sphere>
    </link>

    <gazebo reference="${robot_name}/caster_wheel">
        <material>Gazebo/Grey</material>
        <mu1 value="0.001"/>
        <mu2 value="0.001"/>
    </gazebo>

    <!-- LIDAR SUPPORT LINK-->

    <joint name="${robot_name}/lidar_support_joint" type="fixed">
        <parent link="${robot_name}/chassis"/>
        <child link="${robot_name}/lidar_support"/>
        <origin xyz="0.15 0 0.2"/>
    </joint>

    <link name="${robot_name}/lidar_support">
        <visual>
            <origin xyz="0 0 0.035"/>
            <geometry>
                <cylinder radius="0.05" length="0.07"/>
            </geometry>
            <material name="black"/>
        </visual>
        <collision>
            <origin xyz="0.15 0 0.035"/>
            <geometry>
                <cylinder radius="0.05" length="0.07"/>
            </geometry>
        </collision>
        <xacro:inertial_cylinder mass="0.1" length="0.07" radius="0.05">
            <origin xyz="0 0 0" rpy="0 0 0"/>
        </xacro:inertial_cylinder>

    </link>

    <gazebo reference="${robot_name}/lidar_support">
        <material>Gazebo/Black</material>
    </gazebo>

 
</robot>