<?xml version="1.0"?>
<robot xmlns:xacro="http://www.ros.org/wiki/xacro">

<!-- Ancho: 0.3m , grosor de rueda 0.05m  Alto: 0.6m Largo: 0.6m -->

    <xacro:include filename="inertial_macros.xacro"/>

    <material name="white">
        <color rgba="1 1 1 1"/>
    </material>

    <material name="green">
        <color rgba="0 1 0.5 1"/>
    </material>
    
    <material name="gray">
        <color rgba="0.62 0.62 0.62 1"/>
    </material>

    <material name="red">
        <color rgba="1 0.4 0.4 1"/>
    </material>

    <!-- BASE LINK -->
    <link name="base_link"></link>

    <!-- chassis -->
    <joint name="chassis_joint" type="fixed">
        <parent link="base_link"/>
        <child link="chassis"/>
        <origin xyz="0 0 0"/>
    </joint>
    
    <link name="chassis">
        <visual>
            <origin xyz="0.3 0 -0.14" rpy="${pi/2} 0 ${pi/2}"/>
            <geometry>
                <mesh filename="file://$(find boxbots)/description/meshes/AxeBot/chassis.dae" scale="0.10 0.10 0.10"/>
            </geometry>
            <material name="green"/>
        </visual>
        
        <collision>
            <origin xyz="0.3 0 -0.14" rpy="${pi/2} 0 ${pi/2}"/>
            <geometry>
                <mesh filename="file://$(find boxbots)/description/meshes/AxeBot/chassis.dae" scale="0.09 0.1 0.1"/>
            </geometry>
        </collision>
        <xacro:inertial_box mass="1" x="0.6" y="0.4" z="0.3">
            <origin xyz="0.18 0 0.05" rpy="0 0 0"/>
        </xacro:inertial_box>
    </link>

    <gazebo reference="chassis">
        <material>Gazebo/Turquoise</material>
    </gazebo>

    <!-- LEFT WHEEL -->
    <joint name="left_wheel_joint" type="continuous">
        <parent link="chassis"/>
        <child link="left_wheel"/>
        <!-- y=+(ancho/2+grosor_rueda/2)  -->
        <origin xyz="0 0.225 0"/>
        <axis xyz="0 1 0"/>
    </joint>

    <link name="left_wheel">
        <visual>
            <origin xyz="0.287 -0.225 -0.1427" rpy="${pi/2} 0 ${pi/2}"/>
            <geometry>
                <mesh filename="file://$(find boxbots)/description/meshes/AxeBot/left_wheel.dae" scale="0.10 0.10 0.10"/>
            </geometry>
            <material name="gray"/>
        </visual>
        
        <collision>
            <origin xyz="0.287 -0.225 -0.1427" rpy="${pi/2} 0 ${pi/2}"/>
            <geometry>
                <mesh filename="file://$(find boxbots)/description/meshes/AxeBot/left_wheel.dae" scale="0.10 0.10 0.10"/>
            </geometry>
        </collision>

        <xacro:inertial_cylinder mass="1.0" length="0.05" radius="0.1">
            <origin xyz="0 0 0" rpy="0 0 0"/>
        </xacro:inertial_cylinder>
    </link>

    <gazebo reference="left_wheel">
        <material>Gazebo/Gray</material>
    </gazebo>

    <!-- RIGHT WHEEL -->
    
    <joint name="right_wheel_joint" type="continuous">
        <parent link="chassis"/>
        <child link="right_wheel"/>
        <!-- y=-(ancho/2+grosor_rueda/2)  -->
        <origin xyz="0 -0.225 0"/>
        <axis xyz="0 1 0"/>
    </joint>

    <link name="right_wheel">
        <visual>
            <origin xyz="0.287 0.225 -0.1427" rpy="${pi/2} 0 ${pi/2}"/>
            <geometry>
                <mesh filename="file://$(find boxbots)/description/meshes/AxeBot/right_wheel.dae" scale="0.10 0.10 0.10"/>
            </geometry>
            <material name="gray"/>
        </visual>
        
        <collision>
            <origin xyz="0.287 0.225 -0.1427" rpy="${pi/2} 0 ${pi/2}"/>
            <geometry>
                <mesh filename="file://$(find boxbots)/description/meshes/AxeBot/right_wheel.dae" scale="0.10 0.10 0.10"/>
            </geometry>
        </collision>

        <xacro:inertial_cylinder mass="1.0" length="0.05" radius="0.1">
            <origin xyz="0 0 0" rpy="0 0 0"/>
        </xacro:inertial_cylinder>
    </link>

    <gazebo reference="right_wheel">
        <material>Gazebo/Gray</material>
    </gazebo>

    <!-- BALL WHEEL -->
    <joint name="caster_wheel_joint" type="fixed">
        <parent link="chassis"/>
        <child link="caster_wheel"/>
        <origin xyz="0.36 0 -0.08"/>
    </joint>

    <link name="caster_wheel">
        <visual>
            <origin xyz="-0.06 0 -0.09" rpy="${pi/2} 0 ${pi/2}"/>
            <geometry>
                <mesh filename="file://$(find boxbots)/description/meshes/AxeBot/ball_wheel.dae" scale="0.10 0.10 0.10"/>
            </geometry>
            <material name="white"/>
        </visual>
        
        <collision>
            <origin xyz="-0.06 0 -0.09" rpy="${pi/2} 0 ${pi/2}"/>
            <geometry>
                <mesh filename="file://$(find boxbots)/description/meshes/AxeBot/ball_wheel.dae" scale="0.10 0.10 0.10"/>
            </geometry>
        </collision>

        <xacro:inertial_sphere mass="1.0" radius="0.05">
            <origin xyz="0 0 0" rpy="0 0 0"/>
        </xacro:inertial_sphere>
    </link>

    <gazebo reference="caster_wheel">
        <material>Gazebo/White</material>
        <mu1 value="0.001"/>
        <mu2 value="0.001"/>
    </gazebo>

    <!-- TAIL -->

    <joint name="tail_joint" type="fixed">
        <parent link="chassis"/>
        <child link="tail"/>
        <origin xyz="-0.15 0 0.25"/>
    </joint>

    <link name="tail">
        <visual>
            <origin xyz="0.4 0 -0.43" rpy="${pi/2} 0 ${pi/2}"/>
            <geometry>
                <mesh filename="file://$(find boxbots)/description/meshes/AxeBot/tail.dae" scale="0.10 0.10 0.10"/>
            </geometry>
            <material name="white"/>
        </visual>
        
        <collision>
            <origin xyz="0.4 0 -0.43" rpy="${pi/2} 0 ${pi/2}"/>
            <geometry>
                <mesh filename="file://$(find boxbots)/description/meshes/AxeBot/tail.dae" scale="0.10 0.10 0.10"/>
            </geometry>
        </collision>

        <xacro:inertial_box mass="1" x="0.2" y="0.49" z="0.1">
            <origin xyz="-0.04 0 -0.01" rpy="0 0 0"/>
        </xacro:inertial_box>
    
    </link>

    <gazebo reference="tail">
        <material>Gazebo/YellowGlow</material>
    </gazebo>

    <!-- AXE -->

    <joint name="axe_joint" type="fixed">
        <parent link="chassis"/>
        <child link="axe"/>
        <origin xyz="0.6 0 0.01" />
    </joint>

    <link name="axe">

        <visual>
            <origin xyz="-0.3 0 -0.15" rpy="${pi/2} 0 ${pi/2}"/>
            <geometry>
                <mesh filename="file://$(find boxbots)/description/meshes/AxeBot/axe.dae" scale="0.10 0.10 0.10"/>
            </geometry>
            <material name="red"/>
        </visual>
        
        <collision>
            <origin xyz="-0.3 0 -0.15" rpy="${pi/2} 0 ${pi/2}"/>
            <geometry>
                <mesh filename="file://$(find boxbots)/description/meshes/AxeBot/axe.dae" scale="0.10 0.10 0.10"/>
            </geometry>
        </collision>

        <xacro:inertial_box mass="1" x="0.3" y="0.35" z="0.03">
            <origin xyz="0.04 0 0" rpy="0 0 0"/>
        </xacro:inertial_box>

    
    </link>
    
    <gazebo reference="axe">
        <material>Gazebo/RedGlow</material>
    </gazebo>

    <!-- LIDAR SUPPORT LINK-->

    <joint name="lidar_support_joint" type="fixed">
        <parent link="tail"/>
        <child link="lidar_support"/>
        <origin xyz="-0.07 0 0"/>
    </joint>

    <link name="lidar_support">
        <visual>
            <origin xyz="0 0 0.035"/>
            <geometry>
                <cylinder radius="0.05" length="0.07"/>
            </geometry>
            <material name="red"/>
        </visual>
        
        <collision>
            <origin xyz="0 0 0.035"/>
            <geometry>
                <cylinder radius="0.05" length="0.07"/>
            </geometry>
        </collision>
        

        <xacro:inertial_cylinder mass="0.1" length="0.07" radius="0.05">
            <origin xyz="0 0 0"/>
        </xacro:inertial_cylinder>

    </link>

    <gazebo reference="lidar_support">
        <material>Gazebo/Black</material>
    </gazebo>
</robot>

